Workbook

Sheet Fichas clínicas
A1: CÓDIGO MASCOTA | B1: RUT CLIENTE | C1: NOMBRE | D1: ESPECIE | E1: RAZA | F1: SEXO | G1: COLOR | H1: TATUAJE | I1: CHIP | J1: FECHA NACIMIENTO | K1: PRÓXIMA VACUNACIÓN | L1: PRÓXIMA VACUNACIÓN 2 | M1: PRÓXIMA ANTIRÁBICA | N1: PRÓXIMA DESPARASITACIÓN | O1: PRÓXIMO CONTROL | P1: OBSERVACIÓN | Q1: ESTADO | R1: OBSERVACIONES CERTIFICADO 1 | S1: OBSERVACIONES CERTIFICADO 2 | T1: FECHA CERTIFICADO | U1: DOCTORES | V1: ESTERILIZADO | W1: ALIMENTOS | X1: VACUNA | Y1: VACUNA 2 | Z1: AVISO VAC 1 | AA1: AVISO VAC 2 | AB1: AVISO ANTIRRÁBICA | AC1: AVISO DESPARASITACIÓN | AD1: AVISO CONTROL | AE1: AUX | AF1: ID_ESPECIE | AG1: ESPECIE_RAZA | AH1: ID_RAZA | AI1: SEXO_SIGLA
A2: 1 | B2: 12748091-5 | C2: ABBY | D2: Canis lupus familiaris | E2: Mestizo | F2: Hembra | G2: crema blanco | J2: 2020-08-26 | K2: 2020-12-01 | L2: 0000-00-00 | M2: 0000-00-00 | N2: 2020-12-01 | O2: 0000-00-00 | Q2: 0 | T2: 0000-00-00 | U2: 0 | V2: 0 | W2: 0 | X2: 1 | Y2: 0 | Z2: 0 | AA2: 0 | AB2: 0 | AC2: 0 | AD2: 0 | AE2: =SUBTOTAL(103,E2) -> 1 | AF2: =VLOOKUP(D2,especies!$A$2:$C$9,3,FALSE) -> 1 | AG2: =AF2&"-"&E2 -> 1-Mestizo | AH2: =VLOOKUP('Fichas clínicas'!AG2,razas!$A$2:$D$66,3,FALSE) -> 1 | AI2: =IF(F2="Hembra","H","M") -> H
A3: 2 | B3: 19556213-k | C3: CLOE | D3: Felis silvestris catus | E3: DPC (Doméstico de pelo corto o DSH) | F3: Hembra | G3: NEGRO | J3: 2020-02-01 | K3: 0000-00-00 | L3: 0000-00-00 | M3: 0000-00-00 | N3: 0000-00-00 | O3: 0000-00-00 | T3: 0000-00-00 | U3: 0 | W3: 0 | X3: 0 | Y3: 0 | AE3: =SUBTOTAL(103,E3) -> 1 | AF3: =VLOOKUP(D3,especies!$A$2:$C$9,3,FALSE) -> 2 | AG3: =AF3&"-"&E3 -> 2-DPC (Doméstico de pelo corto o DSH) | AH3: =VLOOKUP('Fichas clínicas'!AG3,razas!$A$2:$D$66,3,FALSE) -> 51 | AI3: =IF(F3="Hembra","H","M") -> H
A4: 3 | B4: 20315385-6 | C4: SIMÓN | D4: Felis silvestris catus | E4: DPC (Doméstico de pelo corto o DSH) | F4: Macho | G4: crema blanco | J4: 2020-09-29 | K4: 0000-00-00 | L4: 0000-00-00 | M4: 0000-00-00 | N4: 0000-00-00 | O4: 0000-00-00 | T4: 0000-00-00 | U4: 0 | W4: 0 | X4: 0 | Y4: 0 | AE4: =SUBTOTAL(103,E4) -> 1 | AF4: =VLOOKUP(D4,especies!$A$2:$C$9,3,FALSE) -> 2 | AG4: =AF4&"-"&E4 -> 2-DPC (Doméstico de pelo corto o DSH) | AH4: =VLOOKUP('Fichas clínicas'!AG4,razas!$A$2:$D$66,3,FALSE) -> 51 | AI4: =IF(F4="Hembra","H","M") -> M
A5: 4 | B5: 19249784-1 | C5: MASHA | D5: Canis lupus familiaris | E5: Mestizo | F5: Hembra | G5: NEGRO | J5: 2020-08-09 | K5: 0000-00-00 | L5: 0000-00-00 | M5: 0000-00-00 | N5: 0000-00-00 | O5: 0000-00-00 | T5: 0000-00-00 | U5: 0 | W5: 0 | X5: 0 | Y5: 0 | AE5: =SUBTOTAL(103,E5) -> 1 | AF5: =VLOOKUP(D5,especies!$A$2:$C$9,3,FALSE) -> 1 | AG5: =AF5&"-"&E5 -> 1-Mestizo | AH5: =VLOOKUP('Fichas clínicas'!AG5,razas!$A$2:$D$66,3,FALSE) -> 1 | AI5: =IF(F5="Hembra","H","M") -> H
A6: 5 | B6: 18590970-0 | C6: KIRA | D6: Canis lupus familiaris | E6: Mestizo | F6: Hembra | G6: NEGRO CAFE | J6: 2018-11-01 | K6: 0000-00-00 | L6: 0000-00-00 | M6: 0000-00-00 | N6: 0000-00-00 | O6: 0000-00-00 | T6: 0000-00-00 | U6: 0 | W6: 0 | X6: 0 | Y6: 0 | AE6: =SUBTOTAL(103,E6) -> 1 | AF6: =VLOOKUP(D6,especies!$A$2:$C$9,3,FALSE) -> 1 | AG6: =AF6&"-"&E6 -> 1-Mestizo | AH6: =VLOOKUP('Fichas clínicas'!AG6,razas!$A$2:$D$66,3,FALSE) -> 1 | AI6: =IF(F6="Hembra","H","M") -> H
A7: 6 | B7: 13160474-2 | C7: BAEL | D7: Felis silvestris catus | E7: DPC (Doméstico de pelo corto o DSH) | F7: Macho | G7: NEGRO CAFE | J7: 2019-01-01 | K7: 0000-00-00 | L7: 0000-00-00 | M7: 0000-00-00 | N7: 0000-00-00 | O7: 0000-00-00 | Q7: 0 | T7: 0000-00-00 | U7: 0 | V7: 1 | W7: 0 | X7: 0 | Y7: 0 | Z7: 0 | AA7: 0 | AB7: 0 | AC7: 0 | AD7: 0 | AE7: =SUBTOTAL(103,E7) -> 1 | AF7: =VLOOKUP(D7,especies!$A$2:$C$9,3,FALSE) -> 2 | AG7: =AF7&"-"&E7 -> 2-DPC (Doméstico de pelo corto o DSH) | AH7: =VLOOKUP('Fichas clínicas'!AG7,razas!$A$2:$D$66,3,FALSE) -> 51 | AI7: =IF(F7="Hembra","H","M") -> M
A8: 7 | B8: 10782898-2 | C8: TOBY | D8: Canis lupus familiaris | E8: Mestizo | F8: Macho | G8: NEGRO CAFE | J8: 2019-06-01 | K8: 0000-00-00 | L8: 0000-00-00 | M8: 0000-00-00 | N8: 0000-00-00 | O8: 0000-00-00 | T8: 0000-00-00 | U8: 0 | W8: 0 | X8: 0 | Y8: 0 | AE8: =SUBTOTAL(103,E8) -> 1 | AF8: =VLOOKUP(D8,especies!$A$2:$C$9,3,FALSE) -> 1 | AG8: =AF8&"-"&E8 -> 1-Mestizo | AH8: =VLOOKUP('Fichas clínicas'!AG8,razas!$A$2:$D$66,3,FALSE) -> 1 | AI8: =IF(F8="Hembra","H","M") -> M
A9: 8 | B9: 11325552-8 | C9: TOBY | D9: Canis lupus familiaris | E9: Fox Terrier Pelo Corto | F9: Macho | G9: blanco cafe negro | J9: 2020-08-17 | K9: 0000-00-00 | L9: 0000-00-00 | M9: 0000-00-00 | N9: 0000-00-00 | O9: 0000-00-00 | T9: 0000-00-00 | U9: 0 | W9: 0 | X9: 0 | Y9: 0 | AE9: =SUBTOTAL(103,E9) -> 1 | AF9: =VLOOKUP(D9,especies!$A$2:$C$9,3,FALSE) -> 1 | AG9: =AF9&"-"&E9 -> 1-Fox Terrier Pelo Corto | AH9: =VLOOKUP('Fichas clínicas'!AG9,razas!$A$2:$D$66,3,FALSE) -> 2 | AI9: =IF(F9="Hembra","H","M") -> M
A10: 9 | B10: 20314994-8 | C10: teodoro | D10: Canis lupus familiaris | E10: Mestizo | F10: Macho | G10: negro cafe blanco | J10: 2020-03-17 | K10: 0000-00-00 | L10: 0000-00-00 | M10: 0000-00-00 | N10: 0000-00-00 | O10: 0000-00-00 | T10: 0000-00-00 | U10: 0 | W10: 0 | X10: 0 | Y10: 0 | AE10: =SUBTOTAL(103,E10) -> 1 | AF10: =VLOOKUP(D10,especies!$A$2:$C$9,3,FALSE) -> 1 | AG10: =AF10&"-"&E10 -> 1-Mestizo | AH10: =VLOOKUP('Fichas clínicas'!AG10,razas!$A$2:$D$66,3,FALSE) -> 1 | AI10: =IF(F10="Hembra","H","M") -> M
A11: 10 | B11: 20016823-2 | C11: POLO | D11: Canis lupus familiaris | E11: Shar-Pei | F11: Macho | G11: cafe | J11: 2019-11-13 | K11: 0000-00-00 | L11: 0000-00-00 | M11: 0000-00-00 | N11: 0000-00-00 | O11: 0000-00-00 | T11: 0000-00-00 | U11: 0 | W11: 0 | X11: 0 | Y11: 0 | AE11: =SUBTOTAL(103,E11) -> 1 | AF11: =VLOOKUP(D11,especies!$A$2:$C$9,3,FALSE) -> 1 | AG11: =AF11&"-"&E11 -> 1-Shar-Pei | AH11: =VLOOKUP('Fichas clínicas'!AG11,razas!$A$2:$D$66,3,FALSE) -> 3 | AI11: =IF(F11="Hembra","H","M") -> M
A12: 11 | B12: 12431326-0 | C12: TOMY | D12: Felis silvestris catus | E12: DPC (Doméstico de pelo corto o DSH) | F12: Macho | G12: GRIS | J12: 2011-11-11 | K12: 0000-00-00 | L12: 0000-00-00 | M12: 0000-00-00 | N12: 0000-00-00 | O12: 0000-00-00 | Q12: 0 | T12: 0000-00-00 | U12: 0 | V12: 1 | W12: 0 | X12: 0 | Y12: 0 | Z12: 0 | AA12: 0 | AB12: 0 | AC12: 0 | AD12: 0 | AE12: =SUBTOTAL(103,E12) -> 1 | AF12: =VLOOKUP(D12,especies!$A$2:$C$9,3,FALSE) -> 2 | AG12: =AF12&"-"&E12 -> 2-DPC (Doméstico de pelo corto o DSH) | AH12: =VLOOKUP('Fichas clínicas'!AG12,razas!$A$2:$D$66,3,FALSE) -> 51 | AI12: =IF(F12="Hembra","H","M") -> M
A13: 12 | B13: 15758791-9 | C13: SASHA | D13: Canis lupus familiaris | E13: Mestizo | F13: Hembra | G13: NEGRO BLANCO | J13: 2020-04-01 | K13: 0000-00-00 | L13: 0000-00-00 | M13: 0000-00-00 | N13: 0000-00-00 | O13: 0000-00-00 | Q13: 0 | T13: 0000-00-00 | U13: 0 | V13: 0 | W13: 0 | X13: 0 | Y13: 0 | Z13: 0 | AA13: 0 | AB13: 0 | AC13: 0 | AD13: 0 | AE13: =SUBTOTAL(103,E13) -> 1 | AF13: =VLOOKUP(D13,especies!$A$2:$C$9,3,FALSE) -> 1 | AG13: =AF13&"-"&E13 -> 1-Mestizo | AH13: =VLOOKUP('Fichas clínicas'!AG13,razas!$A$2:$D$66,3,FALSE) -> 1 | AI13: =IF(F13="Hembra","H","M") -> H
A14: 13 | B14: 19249784-1 | C14: DAISY | D14: Canis lupus familiaris | E14: Mestizo | F14: Hembra | G14: NEGRO BLANCO CAFE | J14: 2020-06-01 | K14: 0000-00-00 | L14: 0000-00-00 | M14: 0000-00-00 | N14: 0000-00-00 | O14: 0000-00-00 | T14: 0000-00-00 | U14: 0 | W14: 0 | X14: 0 | Y14: 0 | AE14: =SUBTOTAL(103,E14) -> 1 | AF14: =VLOOKUP(D14,especies!$A$2:$C$9,3,FALSE) -> 1 | AG14: =AF14&"-"&E14 -> 1-Mestizo | AH14: =VLOOKUP('Fichas clínicas'!AG14,razas!$A$2:$D$66,3,FALSE) -> 1 | AI14: =IF(F14="Hembra","H","M") -> H
A15: 14 | B15: 19249784-1 | C15: REMY | D15: Felis silvestris catus | E15: DPC (Doméstico de pelo corto o DSH) | F15: Macho | G15: NEGRO | J15: 2019-11-01 | K15: 0000-00-00 | L15: 0000-00-00 | M15: 0000-00-00 | N15: 0000-00-00 | O15: 0000-00-00 | T15: 0000-00-00 | U15: 0 | V15: 1 | W15: 0 | X15: 0 | Y15: 0 | AE15: =SUBTOTAL(103,E15) -> 1 | AF15: =VLOOKUP(D15,especies!$A$2:$C$9,3,FALSE) -> 2 | AG15: =AF15&"-"&E15 -> 2-DPC (Doméstico de pelo corto o DSH) | AH15: =VLOOKUP('Fichas clínicas'!AG15,razas!$A$2:$D$66,3,FALSE) -> 51 | AI15: =IF(F15="Hembra","H","M") -> M
A16: 15 | B16: 19249784-1 | C16: MININA | D16: Felis silvestris catus | E16: DPC (Doméstico de pelo corto o DSH) | F16: Hembra | G16: NEGRO AMARILLO | J16: 2020-01-01 | K16: 0000-00-00 | L16: 0000-00-00 | M16: 0000-00-00 | N16: 0000-00-00 | O16: 0000-00-00 | T16: 0000-00-00 | U16: 0 | V16: 1 | W16: 0 | X16: 0 | Y16: 0 | AE16: =SUBTOTAL(103,E16) -> 1 | AF16: =VLOOKUP(D16,especies!$A$2:$C$9,3,FALSE) -> 2 | AG16: =AF16&"-"&E16 -> 2-DPC (Doméstico de pelo corto o DSH) | AH16: =VLOOKUP('Fichas clínicas'!AG16,razas!$A$2:$D$66,3,FALSE) -> 51 | AI16: =IF(F16="Hembra","H","M") -> H
A17: 16 | B17: 11325627-3 | C17: TITA | D17: Felis silvestris catus | E17: DPL (Doméstico de pelo Largo o DLH) | F17: Hembra | G17: GRIS | J17: 2006-11-01 | K17: 0000-00-00 | L17: 0000-00-00 | M17: 0000-00-00 | N17: 0000-00-00 | O17: 0000-00-00 | Q17: 0 | T17: 0000-00-00 | U17: 0 | V17: 1 | W17: 0 | X17: 0 | Y17: 0 | Z17: 0 | AA17: 0 | AB17: 0 | AC17: 0 | AD17: 0 | AE17: =SUBTOTAL(103,E17) -> 1 | AF17: =VLOOKUP(D17,especies!$A$2:$C$9,3,FALSE) -> 2 | AG17: =AF17&"-"&E17 -> 2-DPL (Doméstico de pelo Largo o DLH) | AH17: =VLOOKUP('Fichas clínicas'!AG17,razas!$A$2:$D$66,3,FALSE) -> 52 | AI17: =IF(F17="Hembra","H","M") -> H
A18: 17 | B18: 05175505-7 | C18: SUYAI | D18: Canis lupus familiaris | E18: Mestizo | F18: Hembra | G18: cafe | J18: 2020-04-22 | K18: 0000-00-00 | L18: 0000-00-00 | M18: 0000-00-00 | N18: 0000-00-00 | O18: 0000-00-00 | Q18: 0 | T18: 0000-00-00 | U18: 0 | V18: 1 | W18: 0 | X18: 0 | Y18: 0 | Z18: 0 | AA18: 0 | AB18: 0 | AC18: 0 | AD18: 0 | AE18: =SUBTOTAL(103,E18) -> 1 | AF18: =VLOOKUP(D18,especies!$A$2:$C$9,3,FALSE) -> 1 | AG18: =AF18&"-"&E18 -> 1-Mestizo | AH18: =VLOOKUP('Fichas clínicas'!AG18,razas!$A$2:$D$66,3,FALSE) -> 1 | AI18: =IF(F18="Hembra","H","M") -> H
A19: 18 | B19: 05175505-7 | C19: RAYEN | D19: Canis lupus familiaris | E19: Mestizo | F19: Hembra | G19: CAFÉ | J19: 2020-04-22 | K19: 0000-00-00 | L19: 0000-00-00 | M19: 0000-00-00 | N19: 0000-00-00 | O19: 0000-00-00 | T19: 0000-00-00 | U19: 0 | V19: 1 | W19: 0 | X19: 0 | Y19: 0 | AE19: =SUBTOTAL(103,E19) -> 1 | AF19: =VLOOKUP(D19,especies!$A$2:$C$9,3,FALSE) -> 1 | AG19: =AF19&"-"&E19 -> 1-Mestizo | AH19: =VLOOKUP('Fichas clínicas'!AG19,razas!$A$2:$D$66,3,FALSE) -> 1 | AI19: =IF(F19="Hembra","H","M") -> H
A20: 19 | B20: 22062819-1 | C20: Roberto | D20: Canis lupus familiaris | E20: Mestizo | F20: Macho | G20: blanco | J20: 2020-08-01 | K20: 0000-00-00 | L20: 0000-00-00 | M20: 0000-00-00 | N20: 0000-00-00 | O20: 0000-00-00 | T20: 0000-00-00 | U20: 0 | W20: 0 | X20: 0 | Y20: 0 | AE20: =SUBTOTAL(103,E20) -> 1 | AF20: =VLOOKUP(D20,especies!$A$2:$C$9,3,FALSE) -> 1 | AG20: =AF20&"-"&E20 -> 1-Mestizo | AH20: =VLOOKUP('Fichas clínicas'!AG20,razas!$A$2:$D$66,3,FALSE) -> 1 | AI20: =IF(F20="Hembra","H","M") -> M
A21: 20 | B21: 20707780-1 | C21: FACON | D21: Canis lupus familiaris | E21: Mestizo | F21: Macho | G21: NEGRO BLANCO | J21: 2020-04-12 | K21: 0000-00-00 | L21: 0000-00-00 | M21: 0000-00-00 | N21: 0000-00-00 | O21: 0000-00-00 | T21: 0000-00-00 | U21: 0 | W21: 0 | X21: 0 | Y21: 0 | AE21: =SUBTOTAL(103,E21) -> 1 | AF21: =VLOOKUP(D21,especies!$A$2:$C$9,3,FALSE) -> 1 | AG21: =AF21&"-"&E21 -> 1-Mestizo | AH21: =VLOOKUP('Fichas clínicas'!AG21,razas!$A$2:$D$66,3,FALSE) -> 1 | AI21: =IF(F21="Hembra","H","M") -> M
A22: 21 | B22: 14427559-4 | C22: BLUE | D22: Felis silvestris catus | E22: DPC (Doméstico de pelo corto o DSH) | F22: Macho | G22: ROJO | J22: 2019-11-01 | K22: 2021-11-20 | L22: 0000-00-00 | M22: 2021-06-20 | N22: 0000-00-00 | O22: 0000-00-00 | Q22: 0 | T22: 0000-00-00 | U22: 0 | V22: 1 | W22: 0 | X22: 3 | Y22: 0 | Z22: 0 | AA22: 0 | AB22: 0 | AC22: 0 | AD22: 0 | AE22: =SUBTOTAL(103,E22) -> 1 | AF22: =VLOOKUP(D22,especies!$A$2:$C$9,3,FALSE) -> 2 | AG22: =AF22&"-"&E22 -> 2-DPC (Doméstico de pelo corto o DSH) | AH22: =VLOOKUP('Fichas clínicas'!AG22,razas!$A$2:$D$66,3,FALSE) -> 51 | AI22: =IF(F22="Hembra","H","M") -> M
A23: 22 | B23: 11187385-2 | C23: SASHA | D23: Canis lupus familiaris | E23: Mestizo | F23: Hembra | G23: NEGRO BLANCO | J23: 2012-11-01 | K23: 0000-00-00 | L23: 0000-00-00 | M23: 0000-00-00 | N23: 0000-00-00 | O23: 0000-00-00 | T23: 0000-00-00 | U23: 0 | V23: 1 | W23: 0 | X23: 0 | Y23: 0 | AE23: =SUBTOTAL(103,E23) -> 1 | AF23: =VLOOKUP(D23,especies!$A$2:$C$9,3,FALSE) -> 1 | AG23: =AF23&"-"&E23 -> 1-Mestizo | AH23: =VLOOKUP('Fichas clínicas'!AG23,razas!$A$2:$D$66,3,FALSE) -> 1 | AI23: =IF(F23="Hembra","H","M") -> H
A24: 23 | B24: 18887671-4 | C24: TOM | D24: Canis lupus familiaris | E24: Mestizo | F24: Macho | G24: CREMA | J24: 2020-08-28 | K24: 0000-00-00 | L24: 0000-00-00 | M24: 0000-00-00 | N24: 0000-00-00 | O24: 0000-00-00 | T24: 0000-00-00 | U24: 0 | W24: 0 | X24: 0 | Y24: 0 | AE24: =SUBTOTAL(103,E24) -> 1 | AF24: =VLOOKUP(D24,especies!$A$2:$C$9,3,FALSE) -> 1 | AG24: =AF24&"-"&E24 -> 1-Mestizo | AH24: =VLOOKUP('Fichas clínicas'!AG24,razas!$A$2:$D$66,3,FALSE) -> 1 | AI24: =IF(F24="Hembra","H","M") -> M
A25: 24 | B25: 20346376-6 | C25: KIRA | D25: Canis lupus familiaris | E25: Mestizo | F25: Hembra | G25: NEGRO | J25: 2019-10-01 | K25: 0000-00-00 | L25: 0000-00-00 | M25: 0000-00-00 | N25: 0000-00-00 | O25: 0000-00-00 | T25: 0000-00-00 | U25: 0 | W25: 0 | X25: 0 | Y25: 0 | AE25: =SUBTOTAL(103,E25) -> 1 | AF25: =VLOOKUP(D25,especies!$A$2:$C$9,3,FALSE) -> 1 | AG25: =AF25&"-"&E25 -> 1-Mestizo | AH25: =VLOOKUP('Fichas clínicas'!AG25,razas!$A$2:$D$66,3,FALSE) -> 1 | AI25: =IF(F25="Hembra","H","M") -> H
A26: 25 | B26: 7467495-k | C26: DIANA | D26: Canis lupus familiaris | E26: Caniche | F26: Hembra | G26: BLANCO | J26: 2013-03-19 | K26: 0000-00-00 | L26: 0000-00-00 | M26: 0000-00-00 | N26: 0000-00-00 | O26: 0000-00-00 | T26: 0000-00-00 | U26: 0 | W26: 0 | X26: 0 | Y26: 0 | AE26: =SUBTOTAL(103,E26) -> 1 | AF26: =VLOOKUP(D26,especies!$A$2:$C$9,3,FALSE) -> 1 | AG26: =AF26&"-"&E26 -> 1-Caniche | AH26: =VLOOKUP('Fichas clínicas'!AG26,razas!$A$2:$D$66,3,FALSE) -> 4 | AI26: =IF(F26="Hembra","H","M") -> H
A27: 26 | B27: 5434456-2 | C27: JACK | D27: Canis lupus familiaris | E27: Mestizo | F27: Macho | G27: NEGRO | J27: 2020-03-01 | K27: 0000-00-00 | L27: 0000-00-00 | M27: 0000-00-00 | N27: 0000-00-00 | O27: 0000-00-00 | T27: 0000-00-00 | U27: 0 | W27: 0 | X27: 0 | Y27: 0 | AE27: =SUBTOTAL(103,E27) -> 1 | AF27: =VLOOKUP(D27,especies!$A$2:$C$9,3,FALSE) -> 1 | AG27: =AF27&"-"&E27 -> 1-Mestizo | AH27: =VLOOKUP('Fichas clínicas'!AG27,razas!$A$2:$D$66,3,FALSE) -> 1 | AI27: =IF(F27="Hembra","H","M") -> M
A28: 27 | B28: 17276561-0 | C28: SKY | D28: Canis lupus familiaris | E28: Mestizo | F28: Hembra | G28: CAFÉ | J28: 2020-10-01 | K28: 2020-11-27 | L28: 0000-00-00 | M28: 0000-00-00 | N28: 0000-00-00 | O28: 0000-00-00 | Q28: 0 | T28: 0000-00-00 | U28: 0 | V28: 0 | W28: 0 | X28: 5 | Y28: 0 | Z28: 0 | AA28: 0 | AB28: 0 | AC28: 0 | AD28: 0 | AE28: =SUBTOTAL(103,E28) -> 1 | AF28: =VLOOKUP(D28,especies!$A$2:$C$9,3,FALSE) -> 1 | AG28: =AF28&"-"&E28 -> 1-Mestizo | AH28: =VLOOKUP('Fichas clínicas'!AG28,razas!$A$2:$D$66,3,FALSE) -> 1 | AI28: =IF(F28="Hembra","H","M") -> H
A29: 28 | B29: 10251174-3 | C29: KAISSER | D29: Canis lupus familiaris | E29: Mestizo | F29: Macho | G29: CAFÉ NEGRO | J29: 2020-09-22 | K29: 2020-12-11 | L29: 0000-00-00 | M29: 0000-00-00 | N29: 2020-12-11 | O29: 0000-00-00 | Q29: 0 | T29: 0000-00-00 | U29: 0 | V29: 0 | W29: 0 | X29: 1 | Y29: 0 | Z29: 0 | AA29: 0 | AB29: 0 | AC29: 0 | AD29: 0 | AE29: =SUBTOTAL(103,E29) -> 1 | AF29: =VLOOKUP(D29,especies!$A$2:$C$9,3,FALSE) -> 1 | AG29: =AF29&"-"&E29 -> 1-Mestizo | AH29: =VLOOKUP('Fichas clínicas'!AG29,razas!$A$2:$D$66,3,FALSE) -> 1 | AI29: =IF(F29="Hembra","H","M") -> M
A30: 29 | B30: 16463817-0 | C30: ARON | D30: Canis lupus familiaris | E30: Mestizo | F30: Macho | G30: BLANCO | I30: 900113001676627 | J30: 2020-02-05 | K30: 0000-00-00 | L30: 0000-00-00 | M30: 0000-00-00 | N30: 0000-00-00 | O30: 2020-11-27 | Q30: 0 | T30: 2020-11-20 | U30: 7 | V30: 1 | W30: 0 | X30: 0 | Y30: 0 | Z30: 0 | AA30: 0 | AB30: 0 | AC30: 0 | AD30: 0 | AE30: =SUBTOTAL(103,E30) -> 1 | AF30: =VLOOKUP(D30,especies!$A$2:$C$9,3,FALSE) -> 1 | AG30: =AF30&"-"&E30 -> 1-Mestizo | AH30: =VLOOKUP('Fichas clínicas'!AG30,razas!$A$2:$D$66,3,FALSE) -> 1 | AI30: =IF(F30="Hembra","H","M") -> M
A31: 30 | B31: 14485161-7 | C31: LOCKY | D31: Canis lupus familiaris | E31: Yorkshire Terrier | F31: Macho | G31: NEGRO CAFE | J31: 2017-10-06 | K31: 2021-11-06 | L31: 2021-04-06 | M31: 2021-11-06 | N31: 2021-02-06 | O31: 0000-00-00 | Q31: 0 | T31: 0000-00-00 | U31: 0 | V31: 0 | W31: 0 | X31: 1 | Y31: 6 | Z31: 0 | AA31: 0 | AB31: 0 | AC31: 0 | AD31: 0 | AE31: =SUBTOTAL(103,E31) -> 1 | AF31: =VLOOKUP(D31,especies!$A$2:$C$9,3,FALSE) -> 1 | AG31: =AF31&"-"&E31 -> 1-Yorkshire Terrier | AH31: =VLOOKUP('Fichas clínicas'!AG31,razas!$A$2:$D$66,3,FALSE) -> 5 | AI31: =IF(F31="Hembra","H","M") -> M
A32: 31 | B32: 12430485-7 | C32: LULÚ | D32: Canis lupus familiaris | E32: Poodle | F32: Hembra | G32: NEGRO | J32: 2017-09-18 | K32: 0000-00-00 | L32: 0000-00-00 | M32: 0000-00-00 | N32: 0000-00-00 | O32: 0000-00-00 | Q32: 0 | T32: 0000-00-00 | U32: 0 | V32: 0 | W32: 0 | X32: 0 | Y32: 0 | Z32: 0 | AA32: 0 | AB32: 0 | AC32: 0 | AD32: 0 | AE32: =SUBTOTAL(103,E32) -> 1 | AF32: =VLOOKUP(D32,especies!$A$2:$C$9,3,FALSE) -> 1 | AG32: =AF32&"-"&E32 -> 1-Poodle | AH32: =VLOOKUP('Fichas clínicas'!AG32,razas!$A$2:$D$66,3,FALSE) -> 6 | AI32: =IF(F32="Hembra","H","M") -> H
A33: 32 | B33: 20616154-k | C33: ÁGATHA | D33: Canis lupus familiaris | E33: Mestizo | F33: Hembra | G33: NEGRO | J33: 2020-07-07 | K33: 0000-00-00 | L33: 0000-00-00 | M33: 0000-00-00 | N33: 0000-00-00 | O33: 0000-00-00 | T33: 0000-00-00 | U33: 0 | W33: 0 | X33: 0 | Y33: 0 | AE33: =SUBTOTAL(103,E33) -> 1 | AF33: =VLOOKUP(D33,especies!$A$2:$C$9,3,FALSE) -> 1 | AG33: =AF33&"-"&E33 -> 1-Mestizo | AH33: =VLOOKUP('Fichas clínicas'!AG33,razas!$A$2:$D$66,3,FALSE) -> 1 | AI33: =IF(F33="Hembra","H","M") -> H
A34: 33 | B34: 16159892-5 | C34: ZEUS | D34: Canis lupus familiaris | E34: Mestizo | F34: Macho | G34: NEGRO BLANCO | J34: 2016-10-24 | K34: 0000-00-00 | L34: 0000-00-00 | M34: 0000-00-00 | N34: 0000-00-00 | O34: 0000-00-00 | T34: 0000-00-00 | U34: 0 | W34: 0 | X34: 0 | Y34: 0 | AE34: =SUBTOTAL(103,E34) -> 1 | AF34: =VLOOKUP(D34,especies!$A$2:$C$9,3,FALSE) -> 1 | AG34: =AF34&"-"&E34 -> 1-Mestizo | AH34: =VLOOKUP('Fichas clínicas'!AG34,razas!$A$2:$D$66,3,FALSE) -> 1 | AI34: =IF(F34="Hembra","H","M") -> M
A35: 34 | B35: 17511757-1 | C35: VITO | D35: Canis lupus familiaris | E35: Shih Tzu | F35: Macho | G35: CREMA | J35: 2018-10-06 | K35: 0000-00-00 | L35: 0000-00-00 | M35: 0000-00-00 | N35: 0000-00-00 | O35: 0000-00-00 | T35: 0000-00-00 | U35: 0 | V35: 1 | W35: 0 | X35: 0 | Y35: 0 | AE35: =SUBTOTAL(103,E35) -> 1 | AF35: =VLOOKUP(D35,especies!$A$2:$C$9,3,FALSE) -> 1 | AG35: =AF35&"-"&E35 -> 1-Shih Tzu | AH35: =VLOOKUP('Fichas clínicas'!AG35,razas!$A$2:$D$66,3,FALSE) -> 7 | AI35: =IF(F35="Hembra","H","M") -> M
A36: 35 | B36: 8785568-6 | C36: TROMPITO | D36: Canis lupus familiaris | E36: Teckel | F36: Macho | G36: CAFE | J36: 2018-02-09 | K36: 0000-00-00 | L36: 0000-00-00 | M36: 0000-00-00 | N36: 0000-00-00 | O36: 0000-00-00 | T36: 0000-00-00 | U36: 0 | W36: 0 | X36: 0 | Y36: 0 | AE36: =SUBTOTAL(103,E36) -> 1 | AF36: =VLOOKUP(D36,especies!$A$2:$C$9,3,FALSE) -> 1 | AG36: =AF36&"-"&E36 -> 1-Teckel | AH36: =VLOOKUP('Fichas clínicas'!AG36,razas!$A$2:$D$66,3,FALSE) -> 8 | AI36: =IF(F36="Hembra","H","M") -> M
A37: 36 | B37: 15625676-5 | C37: OZZY | D37: Felis silvestris catus | E37: DPC (Doméstico de pelo corto o DSH) | F37: Macho | G37: ROJO BLANCO | J37: 2020-09-21 | K37: 0000-00-00 | L37: 0000-00-00 | M37: 0000-00-00 | N37: 0000-00-00 | O37: 0000-00-00 | Q37: 0 | T37: 0000-00-00 | U37: 0 | V37: 0 | W37: 0 | X37: 0 | Y37: 0 | Z37: 0 | AA37: 0 | AB37: 0 | AC37: 0 | AD37: 0 | AE37: =SUBTOTAL(103,E37) -> 1 | AF37: =VLOOKUP(D37,especies!$A$2:$C$9,3,FALSE) -> 2 | AG37: =AF37&"-"&E37 -> 2-DPC (Doméstico de pelo corto o DSH) | AH37: =VLOOKUP('Fichas clínicas'!AG37,razas!$A$2:$D$66,3,FALSE) -> 51 | AI37: =IF(F37="Hembra","H","M") -> M
A38: 37 | B38: 19556027-7 | C38: SOFIA | D38: Felis silvestris catus | E38: DPC (Doméstico de pelo corto o DSH) | F38: Hembra | G38: ROJO BLANCO | J38: 2015-02-02 | K38: 0000-00-00 | L38: 0000-00-00 | M38: 0000-00-00 | N38: 0000-00-00 | O38: 0000-00-00 | T38: 0000-00-00 | U38: 0 | V38: 1 | W38: 0 | X38: 0 | Y38: 0 | AE38: =SUBTOTAL(103,E38) -> 1 | AF38: =VLOOKUP(D38,especies!$A$2:$C$9,3,FALSE) -> 2 | AG38: =AF38&"-"&E38 -> 2-DPC (Doméstico de pelo corto o DSH) | AH38: =VLOOKUP('Fichas clínicas'!AG38,razas!$A$2:$D$66,3,FALSE) -> 51 | AI38: =IF(F38="Hembra","H","M") -> H
A39: 38 | B39: 19249784-1 | C39: ANTEUS | D39: Canis lupus familiaris | E39: Mestizo | F39: Macho | G39: AMARILLO BLANCO NEGRO | J39: 2020-04-01 | K39: 0000-00-00 | L39: 0000-00-00 | M39: 0000-00-00 | N39: 0000-00-00 | O39: 0000-00-00 | T39: 0000-00-00 | U39: 0 | W39: 0 | X39: 0 | Y39: 0 | AE39: =SUBTOTAL(103,E39) -> 1 | AF39: =VLOOKUP(D39,especies!$A$2:$C$9,3,FALSE) -> 1 | AG39: =AF39&"-"&E39 -> 1-Mestizo | AH39: =VLOOKUP('Fichas clínicas'!AG39,razas!$A$2:$D$66,3,FALSE) -> 1 | AI39: =IF(F39="Hembra","H","M") -> M
A40: 39 | B40: 17283582-1 | C40: JULIETA | D40: Felis silvestris catus | E40: DPC (Doméstico de pelo corto o DSH) | F40: Hembra | G40: GRIS | J40: 2019-09-14 | K40: 0000-00-00 | L40: 0000-00-00 | M40: 0000-00-00 | N40: 0000-00-00 | O40: 0000-00-00 | T40: 0000-00-00 | U40: 0 | V40: 1 | W40: 0 | X40: 0 | Y40: 0 | AE40: =SUBTOTAL(103,E40) -> 1 | AF40: =VLOOKUP(D40,especies!$A$2:$C$9,3,FALSE) -> 2 | AG40: =AF40&"-"&E40 -> 2-DPC (Doméstico de pelo corto o DSH) | AH40: =VLOOKUP('Fichas clínicas'!AG40,razas!$A$2:$D$66,3,FALSE) -> 51 | AI40: =IF(F40="Hembra","H","M") -> H
...

Sheet paciente_tutor
A1: ID_MASCOTA | B1: RUT | C1: NOMBRE_TUTOR | D1: RUT_TUTOR_CON_DATOS
A2: ='Fichas clínicas'!A2 -> 1 | B2: ='Fichas clínicas'!B2 -> 12748091-5 | C2: =VLOOKUP(paciente_tutor!B2,clientes!A2:B1583,2,FALSE) -> Cristina | D2: =IF(C2="#N/A","",B2) -> 12748091-5
A3: ='Fichas clínicas'!A3 -> 2 | B3: ='Fichas clínicas'!B3 -> 19556213-k | C3: =VLOOKUP(paciente_tutor!B3,clientes!A3:B1584,2,FALSE) -> NATACHA | D3: =IF(C3="#N/A","",B3) -> 19556213-k
A4: ='Fichas clínicas'!A4 -> 3 | B4: ='Fichas clínicas'!B4 -> 20315385-6 | C4: =VLOOKUP(paciente_tutor!B4,clientes!A4:B1585,2,FALSE) -> JORDAN | D4: =IF(C4="#N/A","",B4) -> 20315385-6
A5: ='Fichas clínicas'!A5 -> 4 | B5: ='Fichas clínicas'!B5 -> 19249784-1 | C5: =VLOOKUP(paciente_tutor!B5,clientes!A5:B1586,2,FALSE) -> DOMINIQUE | D5: =IF(C5="#N/A","",B5) -> 19249784-1
A6: ='Fichas clínicas'!A6 -> 5 | B6: ='Fichas clínicas'!B6 -> 18590970-0 | C6: =VLOOKUP(paciente_tutor!B6,clientes!A6:B1587,2,FALSE) -> ANTONIO | D6: =IF(C6="#N/A","",B6) -> 18590970-0
A7: ='Fichas clínicas'!A7 -> 6 | B7: ='Fichas clínicas'!B7 -> 13160474-2 | C7: =VLOOKUP(paciente_tutor!B7,clientes!A7:B1588,2,FALSE) -> DANIEL ALEJANDRO | D7: =IF(C7="#N/A","",B7) -> 13160474-2
A8: ='Fichas clínicas'!A8 -> 7 | B8: ='Fichas clínicas'!B8 -> 10782898-2 | C8: =VLOOKUP(paciente_tutor!B8,clientes!A8:B1589,2,FALSE) -> Patricio | D8: =IF(C8="#N/A","",B8) -> 10782898-2
A9: ='Fichas clínicas'!A9 -> 8 | B9: ='Fichas clínicas'!B9 -> 11325552-8 | C9: =VLOOKUP(paciente_tutor!B9,clientes!A9:B1590,2,FALSE) -> Jimena | D9: =IF(C9="#N/A","",B9) -> 11325552-8
A10: ='Fichas clínicas'!A10 -> 9 | B10: ='Fichas clínicas'!B10 -> 20314994-8 | C10: =VLOOKUP(paciente_tutor!B10,clientes!A10:B1591,2,FALSE) -> Francisca Antonia | D10: =IF(C10="#N/A","",B10) -> 20314994-8
A11: ='Fichas clínicas'!A11 -> 10 | B11: ='Fichas clínicas'!B11 -> 20016823-2 | C11: =VLOOKUP(paciente_tutor!B11,clientes!A11:B1592,2,FALSE) -> Mitcheel Cristina Alexandra | D11: =IF(C11="#N/A","",B11) -> 20016823-2
A12: ='Fichas clínicas'!A12 -> 11 | B12: ='Fichas clínicas'!B12 -> 12431326-0 | C12: =VLOOKUP(paciente_tutor!B12,clientes!A12:B1593,2,FALSE) -> JUAN CARLOS | D12: =IF(C12="#N/A","",B12) -> 12431326-0
A13: ='Fichas clínicas'!A13 -> 12 | B13: ='Fichas clínicas'!B13 -> 15758791-9 | C13: =VLOOKUP(paciente_tutor!B13,clientes!A13:B1594,2,FALSE) -> Magdalena Andrea | D13: =IF(C13="#N/A","",B13) -> 15758791-9
... A2357: ='Fichas clínicas'!A2357 -> 2359 | B2357: ='Fichas clínicas'!B2357 -> 16238905-k | C2357: =VLOOKUP(paciente_tutor!B2357,clientes!A2357:B3938,2,FALSE) -> #N/A | D2357: =IF(C2357="#N/A","",B2357) -> #N/A

Sheet clientes
A1: Rut | B1: Nombres | C1: ApPaterno | D1: ApMaterno | E1: Calle | F1: Numero | G1: Region | H1: Comuna | I1: Telefono | J1: Telefono2 | K1: Celular | L1: Celular2 | M1: Email | N1: Observaciones | O1: RazonSocial | P1: Giro | Q1: Contacto
A2: 05175505-7 | B2: JANA | C2: ARRIAGADA | D2: RIEDEMANN | E2: CONDOMINIO RIVERAS DE MIRAFLORES | F2: PARCELA 47 | G2: Región de Los Ríos | H2: VALDIVIA | I2: 978769097 | M2: JANAVALDIVIA@YAHOO.COM
A3: 10016177-k | B3: Marcela | C3: Salazar | D3: Figueroa | E3: Rio Imperial | F3: 4048 | G3: Región de Los Ríos | H3: VALDIVIA | I3: 977672542
A4: 10020390-1 | B4: Jessica | C4: Villablanca | D4: Ugalde | E4: los pelues | F4: 059 | G4: Región de Los Ríos | H4: VALDIVIA | I4: 95433056
A5: 10048099-9 | B5: CAROLINA | C5: ARAYA | D5: PARRA | E5: LAS VIVUÑAS | F5: 1680 | G5: Región de Los Ríos | H5: VALDIVIA | K5: 991342485
A6: 10051505-9 | B6: Amands | C6: Busto | D6: Ferreira | E6: Av raul Saex | F6: 1701 | G6: Región de Los Ríos | H6: VALDIVIA
A7: 10052627-1 | B7: Luciano | C7: Gatica | D7: Soto | E7: Pasaje 5º | F7: 3145 | G7: Región de Los Ríos | H7: VALDIVIA | I7: 959770229
A8: 10065078-9 | B8: Claudio | C8: Villegas | D8: Pérez | E8: Puerto natales | F8: 378 | G8: Región de Los Ríos | H8: VALDIVIA | I8: 982379815
A9: 10073818-k | B9: CARLOS | C9: PALACIOS | D9: CUEVAS | E9: LOS PEUCOS | F9: 1835 | G9: Región de Los Ríos | H9: VALDIVIA | I9: 952767013
A10: 10146302-8 | B10: Miriam | C10: Colimilla | D10: Pichun | E10: Doctor Dabbe | F10: 046 | G10: Región de Los Ríos | H10: VALDIVIA | I10: 955173723 | M10: miriam.luzcp64@gmail.com
A11: 10150042-k | B11: Marta | C11: Lopez | D11: Gonzalez | E11: Altos guacamayo pasaje mapu | F11: 636 | G11: Región de Los Ríos | H11: VALDIVIA | I11: 94292246
A12: 10162153-7 | B12: Alicia | C12: Figueroa | D12: Rivera | E12: Raamon Soto Mayor | F12: 172 | G12: Región de Los Ríos | H12: VALDIVIA | I12: 985399058
A13: 10169509-3 | B13: Elizabeth | C13: Nova | D13: Guajardo | E13: Calle Rodolfo Beckdorf 1785 | F13: 1785 | G13: Región de Los Ríos | H13: VALDIVIA | I13: 968447004
A14: 10181972-8 | B14: Benita | C14: Arauco | D14: Chupin | E14: Los naranjos | F14: 613 | G14: Región de Los Ríos | H14: VALDIVIA | I14: 940536454
A15: 10209704-1 | B15: SILVIA | C15: CHEUQUIAN | D15: CAMAN | E15: LAS AGUILAS | F15: 547 | G15: Región de Los Ríos | H15: VALDIVIA | K15: 989561532
A16: 10251174-3 | B16: ALFREDO | C16: ACEVEDO | D16: SANCHEZ | E16: INT. JOSÉ ANTONIO DE LA CAVADERA | F16: 4478 | G16: Región de Los Ríos | H16: VALDIVIA | I16: 978253724 (Isabel) | K16: 984339080 | M16: wenceslao.acevedos@gmail.com
A17: 10259315-4 | B17: JUANA | C17: HERMOSILLA | D17: BAEZ | E17: LOS JILGUEROS | F17: 663 | G17: Región de Los Ríos | H17: VALDIVIA | K17: 994752655
A18: 10266974-6 | B18: Angélica | C18: Sanchez | D18: Perez | E18: pasaje Carboneros | F18: 876 | G18: Región de Los Ríos | H18: RIO BUENO | I18: 964249430
A19: 10283044-k | B19: ABELARDO | C19: MIRANDA | D19: RUIZ | E19: SAN ANTONIO S/N PELCHUQUIN | F19: 0000 | G19: Región de Los Ríos | H19: MARIQUINA | K19: 99643712 | M19: abelardo4.miranda@gmail.com
A20: 10287799-3 | B20: Rodrigo | C20: VASQUEZ | D20: Peña | E20: LUIS DAMANN ASENJO | F20: 832 | G20: Región de Los Ríos | H20: VALDIVIA | I20: 86617446
A21: 10288313-6 | B21: GUIDO | C21: CACERES | D21: CERDA | E21: ALONSO VILLANUEVA | F21: 461 | G21: Región de Los Ríos | H21: VALDIVIA | K21: 978581734 | M21: gcacerescerda@gmail.com
A22: 10293718-K | B22: Ana Maria | C22: Huile | D22: Carrasco | E22: Luis Damman | F22: 2194 | G22: Región de Los Ríos | H22: VALDIVIA | I22: 967619650
A23: 10314354-3 | B23: Yasna | C23: Becerra | D23: Guajardo | E23: Marcelo Serra Soyer . | F23: 701 | G23: Región de Los Ríos | H23: VALDIVIA | I23: 956184337 | M23: yasnabecerrag@gmail.com
A24: 10324109-K | B24: JOSE LUIS | C24: GUZMAN | D24: SOTO | E24: FELIX GARCIA | F24: 968 | G24: Región de Los Ríos | H24: VALDIVIA | I24: 78685517
A25: 10327188-6 | B25: Eliana | C25: Reyes | D25: Bello | E25: José Ignacio Valdés | F25: 410 | G25: Región de Los Ríos | H25: VALDIVIA | I25: 965288803
A26: 10346203-7 | B26: María | C26: Malpu | D26: Imigo | E26: luis damann | F26: 2062 | G26: Región de Los Ríos | H26: VALDIVIA | I26: 988115092
A27: 10357103-0 | B27: Sandra | C27: Galilea | D27: Hermosilla | E27: Domeyko | F27: 303 | G27: Región de Los Ríos | H27: VALDIVIA | I27: 966786953 | M27: sandragalilea@gmail.com
A28: 10372205-5 | B28: Leticia | C28: Roa | D28: Henriquez | E28: Ricardo Olea | F28: 932 | G28: Región de Los Ríos | H28: VALDIVIA | I28: 977344044 | M28: coke_6668@hotmail.com
A29: 10387154-9 | B29: ALDA | C29: SOTO | D29: PEREZ | E29: NUEVA 2 | F29: 3082 | G29: Región de Los Ríos | H29: VALDIVIA | K29: 968013416
A30: 10396824-0 | B30: VIOLETA | C30: CARRILLO | D30: GUARDA | E30: AV, RAUL SAEZ | F30: 1705 | G30: Región de Los Ríos | H30: VALDIVIA | K30: 66332890
A31: 10427235-5 | B31: Verónica | C31: Quezada | D31: Fontanilla | E31: Gaspar de ahumada | F31: 065 | G31: Región de Los Ríos | H31: VALDIVIA | I31: 91214160
A32: 10438889-2 | B32: Veronica Cecilia | C32: Rosales | D32: Vio | E32: venezuela | F32: 1003 | G32: Región de Los Ríos | H32: VALDIVIA | I32: 89181510 | M32: veronicaceciliavio@gmail.com
A33: 10442254-3 | B33: Patricia Alejandra | C33: Gonzalez | D33: Monsalve | E33: Las gaviotas | F33: poste 5 | G33: Región de Los Ríos | H33: VALDIVIA | L33: 989773945
A34: 10442417-1 | B34: BERTA ANDREA | C34: JARAMILLO | D34: LEIVA | E34: LOS KENAS | F34: 1852 | G34: Región de Los Ríos | H34: VALDIVIA | K34: 998440204
A35: 10442429-5 | B35: Valesca | C35: Navarrete | D35: Velasquez | E35: los quenas | F35: 1840 | G35: Región de Los Ríos | H35: VALDIVIA | I35: 89240453
A36: 10465719-2 | B36: Sandra | C36: García | D36: Santana | E36: Itahue | F36: 406 | G36: Región de Los Ríos | H36: VALDIVIA | I36: 990307740 | M36: cor_entertrise@hotmail.com
A37: 10473035-3 | B37: Oscar | C37: Santana | D37: Herrera | E37: Río Calle calle | F37: 4088 | G37: Región de Los Ríos | H37: VALDIVIA | I37: 988479203
A38: 10502957-8 | B38: GLORIA RUTH | C38: VELASQUEZ | D38: NAVARRETE | E38: PASAJE LAS AGUILAS | F38: 591 | G38: Región de Los Ríos | H38: VALDIVIA | I38: 964458487 | M38: GV227062@GMAIL.COM
A39: 10518589-8 | B39: ALEJANDRINA | C39: VELASQUEZ | D39: MONTAÑA | E39: LOS ROMEROS | F39: 547 | G39: Región de Los Ríos | H39: VALDIVIA | K39: 986452773
A40: 10529851-k | B40: AIDES | C40: SALGADO | D40: RIOS | E40: LOS NARANJOS | F40: 966 | G40: Región de Los Ríos | H40: VALDIVIA | K40: 986162534 | M40: MIGUELMSALGADO@OUTLOOK.COM
...

Sheet especies
A1: nombre_especie | B1: nombre_comun | C1: id_especie
A2: Canis lupus familiaris | B2: Perro | C2: 1
A3: Felis silvestris catus | B3: Gato | C3: 2
A4: Otra | B4: Otra | C4: 3
A5: Erinaceidae | B5: Erizo | C5: 4
A6: Cricetinos | B6: Hamster | C6: 5
A7: Oryctolagus cuniculus | B7: Conejo | C7: 6
A8: Quelonios | B8: Tortuga | C8: 7
A9: Cavia porcellus (cobayos) | B9: Cuy | C9: 8

Sheet razas
A1: especie-raza | B1: nombre | C1: id_raza | D1: id_especie
A2: =D2&"-"&B2 -> 1-Mestizo | B2: Mestizo | C2: 1 | D2: 1
A3: =D3&"-"&B3 -> 1-Fox Terrier Pelo Corto | B3: Fox Terrier Pelo Corto | C3: 2 | D3: 1
A4: =D4&"-"&B4 -> 1-Shar-Pei | B4: Shar-Pei | C4: 3 | D4: 1
A5: =D5&"-"&B5 -> 1-Caniche | B5: Caniche | C5: 4 | D5: 1
A6: =D6&"-"&B6 -> 1-Yorkshire Terrier | B6: Yorkshire Terrier | C6: 5 | D6: 1
A7: =D7&"-"&B7 -> 1-Poodle | B7: Poodle | C7: 6 | D7: 1
A8: =D8&"-"&B8 -> 1-Shih Tzu | B8: Shih Tzu | C8: 7 | D8: 1
A9: =D9&"-"&B9 -> 1-Teckel | B9: Teckel | C9: 8 | D9: 1
A10: =D10&"-"&B10 -> 1-Chow-Chow | B10: Chow-Chow | C10: 9 | D10: 1
A11: =D11&"-"&B11 -> 1-Terrier Chileno | B11: Terrier Chileno | C11: 10 | D11: 1
A12: =D12&"-"&B12 -> 1-Pug | B12: Pug | C12: 11 | D12: 1
A13: =D13&"-"&B13 -> 1-Ovejero Alemán | B13: Ovejero Alemán | C13: 12 | D13: 1
... A66: =D66&"-"&B66 -> 8-Americana | B66: Americana | C66: 65 | D66: 8

Sheet funcion_lista_razas
A1: {=_xlfn.UNIQUE(IF('Fichas clínicas'!AE2:AE2357=1,'Fichas clínicas'!E2:E2357,""))} -> Mestizo | E1: Perro | F1: Gato | G1: Otra | H1: Erizo | I1: Hamster | J1: Conejo | K1: Tortuga | L1: Cuy
A2: DPC (Doméstico de pelo corto o DSH) | E2: Mestizo | F2: DPC (Doméstico de pelo corto o DSH) | G2: Otra | H2: Erizo de Tierra | I2: Hamster Dorado | J2: Enana | K2: Tortuga de oreja roja | L2: Americana
A3: Fox Terrier Pelo Corto | E3: Fox Terrier Pelo Corto | F3: DPL (Doméstico de pelo Largo o DLH) | I3: Hamster Chino | J3: Cabeza de León
A4: Shar-Pei | E4: Shar-Pei | F4: Británico de Pelo Corto | J4: Conejo Doméstico
A5: DPL (Doméstico de pelo Largo o DLH) | E5: Caniche | F5: Persa | J5: Conejo Angora
A6: Caniche | E6: Yorkshire Terrier | J6: Orejas Caidas
A7: Yorkshire Terrier | E7: Poodle
A8: Poodle | E8: Shih Tzu
A9: Shih Tzu | E9: Teckel
A10: Teckel | E10: Chow-Chow
A11: Chow-Chow | E11: Terrier Chileno
A12: Otra | E12: Pug
A13: Terrier Chileno | E13: Ovejero Alemán
A14: Pug | E14: Beagle
A15: Ovejero Alemán | E15: Boxer
A16: Beagle | E16: Akita Americano
A17: Boxer | E17: Golden Retriever
A18: Akita Americano | E18: Malamute de Alaska
... A51: Conejo Doméstico | E51: Dobermann
A52: Tortuga de oreja roja
A53: Americana
A54: Staffordshire Terrier Americano
A55: Hamster Chino
A56: Bulldog
A57: Conejo Angora
A58: Schnauzer Miniatura
A59: Jack Russell terrier
A60: Braco de Ariege
A61: Persa
A62: Orejas Caidas
A63: Pequinés
... A65: Dobermann
